[33mWARNING [0m urllib3.connectionpool:connectionpool.py:812 Retrying (Retry(total=2, connect=None, read=None, redirect=None, status=None)) after connection broken by 'NewConnectionError('<urllib3.connection.HTTPConnection object at 0x10db26e90>: Failed to establish a new connection: [Errno 61] Connection refused')': /wd/hub/session
[33mWARNING [0m urllib3.connectionpool:connectionpool.py:812 Retrying (Retry(total=1, connect=None, read=None, redirect=None, status=None)) after connection broken by 'NewConnectionError('<urllib3.connection.HTTPConnection object at 0x10db26d40>: Failed to establish a new connection: [Errno 61] Connection refused')': /wd/hub/session
[33mWARNING [0m urllib3.connectionpool:connectionpool.py:812 Retrying (Retry(total=0, connect=None, read=None, redirect=None, status=None)) after connection broken by 'NewConnectionError('<urllib3.connection.HTTPConnection object at 0x10db26b60>: Failed to establish a new connection: [Errno 61] Connection refused')': /wd/hub/session
[33mWARNING [0m urllib3.connectionpool:connectionpool.py:812 Retrying (Retry(total=2, connect=None, read=None, redirect=None, status=None)) after connection broken by 'NewConnectionError('<urllib3.connection.HTTPConnection object at 0x10dc3edd0>: Failed to establish a new connection: [Errno 61] Connection refused')': /wd/hub/session
[33mWARNING [0m urllib3.connectionpool:connectionpool.py:812 Retrying (Retry(total=1, connect=None, read=None, redirect=None, status=None)) after connection broken by 'NewConnectionError('<urllib3.connection.HTTPConnection object at 0x10dc3df90>: Failed to establish a new connection: [Errno 61] Connection refused')': /wd/hub/session
[33mWARNING [0m urllib3.connectionpool:connectionpool.py:812 Retrying (Retry(total=0, connect=None, read=None, redirect=None, status=None)) after connection broken by 'NewConnectionError('<urllib3.connection.HTTPConnection object at 0x10dc3dd80>: Failed to establish a new connection: [Errno 61] Connection refused')': /wd/hub/session